Workbook
Name L_REM_GERAL: PARAMETROS!$B$5
Name L_REM_PFMEI: PARAMETROS!$B$6
Name L_FORNECEDOR: PARAMETROS!$B$7
Name L_ADM: PARAMETROS!$B$8
Name L_ACESS: PARAMETROS!$B$9
Name L_DIVULG: PARAMETROS!$B$10
Name L_CAPT_PCT: PARAMETROS!$B$11
Name L_CAPT_TETO: PARAMETROS!$B$12
Name L_CACHE_SOLO: PARAMETROS!$B$13
Name L_CACHE_GRUPO: PARAMETROS!$B$14
Name L_CACHE_MUSICO: PARAMETROS!$B$15
Name L_CACHE_MAESTRO: PARAMETROS!$B$16
Name L_CACHE_PALESTRA: PARAMETROS!$B$17
Name L_INICIANTE: PARAMETROS!$B$18
Name L_DIST_PATROC: PARAMETROS!$B$19
Name L_DIST_PROPON: PARAMETROS!$B$20
Name L_DIST_SOCIAL: PARAMETROS!$B$21
Name L_DIST_POPULAR: PARAMETROS!$B$22
Name L_PRECO_POPULAR: PARAMETROS!$B$23
Name L_TICKET_MEDIO: PARAMETROS!$B$24
Name L_PF_QTD: PARAMETROS!$B$25
Name L_PF_TETO: PARAMETROS!$B$26
Name L_MEI_QTD: PARAMETROS!$B$27
Name L_MEI_TETO: PARAMETROS!$B$28
Name L_PJ_QTD: PARAMETROS!$B$29
Name L_PJ_TETO: PARAMETROS!$B$30
Name MARGEM: PARAMETROS!$B$31
Name LISTA_CATEGORIAS: PARAMETROS!$I$5:$I$17
Name TAB_CATEGORIAS: PARAMETROS!$I$5:$J$17
Name LISTA_ETAPAS: PARAMETROS!$L$5:$L$12
Name VALOR_INCENTIVO: 'ORÇAMENTO'!$C$3
Name VALOR_OUTRAS: 'ORÇAMENTO'!$C$4
Name VALOR_TOTAL: 'ORÇAMENTO'!$C$5
Name DIST_STATUS1: DISTRIBUICAO!$G$7
Name VALOR_PROJETO: 'RADAR DE LIMITES'!$B$9
Name VALOR_CAPTADO: 'RADAR DE LIMITES'!$B$12
Name TIPO_PROP: 'RADAR DE LIMITES'!$B$5

Sheet COMECE AQUI
A1: ROUANET 31/10 — Planilhas de Execução
A2: Kit de organização e conferência. Não garante aprovação nem captação. Base normativa: Lei 8.313/1991, Decreto 11.453/2023 e IN MinC nº 29/2026 (verificação: 25/09/2026). Sempre confira a norma vigente no site do Ministério da Cultura.
A4: ORDEM | B4: ABA | C4: O QUE FAZER | D4: TEMPO
A5: 1 | B5: PARAMETROS | C5: Confira se os limites estão iguais aos da norma vigente. Só altere se a norma mudar (células amarelas). | D5: 5 min
A6: 2 | B6: MAPA DO PROJETO | C6: Preencha a ideia do projeto campo a campo. É o texto-base do Salic. | D6: 2–3 h
A7: 3 | B7: ORÇAMENTO | C7: Lance cada despesa. Preencha também as colunas cinza de conferência (categoria, vínculo, preço, dupla cobertura). | D7: 2–4 h
A8: 4 | B8: CRONOGRAMA | C8: Lance as atividades com início e fim. O gráfico de barras e os alertas aparecem sozinhos. | D8: 1 h
A9: 5 | B9: DISTRIBUICAO | C9: Informe quantos ingressos/produtos existem e como serão distribuídos. | D9: 30 min
A10: 6 | B10: RADAR DE LIMITES | C10: Informe tipo de proponente e cenário de captação. Leia os status 🟢🟡🔴. | D10: 20 min
A11: 7 | B11: MATRIZ CONSISTENCIA | C11: Ligue cada objetivo a meta, produto, despesa, atividade e público. | D11: 40 min
A12: 8 | B12: CHECKLIST DOCUMENTOS | C12: Marque o que se aplica e o que você já tem. | D12: 30 min
A13: 9 | B13: CHECKLIST SALIC | C13: Use ao preencher o sistema, etapa por etapa. | D13: durante o Salic
A14: 10 | B14: CHECKLIST FINAL | C14: 50 verificações antes de clicar em enviar. Meta: zero 'NÃO'. | D14: 40 min
A15: 11 | B15: CONTROLE NORMATIVO | C15: Registre a data em que você conferiu a norma oficial. | D15: 5 min
A17: LEGENDA DE CORES
B18: Amarelo claro = você preenche
B19: Cinza = fórmula automática (não apague)
B20: 🟢 = dentro do limite / conferido / coerente
B21: 🟡 = verificar / revisar (perto do limite ou informação faltando)
B22: 🔴 = acima do limite / risco alto / inconsistente
A24: REGRA DE OURO | B24: SE NÃO CONSIGO EXPLICAR POR QUE ESSA DESPESA EXISTE, NÃO COLOQUE A DESPESA.
A26: IMPORTANTE: as calculadoras são ferramentas de CONFERÊNCIA prévia. O Salic aplica as fórmulas oficiais e o Ministério da Cultura faz a análise técnica. 🟢 na planilha não significa aprovação — significa apenas que o número informado está dentro do limite configurado na aba PARAMETROS.

Sheet PARAMETROS
A1: PARÂMETROS NORMATIVOS (IN MinC nº 29/2026)
A2: Células amarelas = limites usados por todas as calculadoras. Confira cada linha no texto oficial antes de usar. Se a norma mudar, altere aqui.
A4: Regra | B4: Limite | C4: Base de cálculo | D4: Quem está sujeito | E4: Exceções / observações | F4: Fonte (confira no texto oficial) | G4: Status da verificação | I4: Categorias de limite (listas) | J4: Limite unitário | L4: Etapas
A5: Remuneração do proponente – regra geral | B5: 0.2 | C5: VALOR CAPTADO | D5: Proponente que presta serviço ao projeto previsto no orçamento analítico. Pagamentos a cônjuge, companheiro(a), empresa coligada ou com sócio em comum SOMAM neste limite. | E5: Não se aplica a grupos artísticos familiares, corpos artísticos estáveis e grupos/coletivos culturais que atuem na execução do projeto (ver texto oficial). PF e MEI têm limite próprio (linha abaixo). | F5: IN MinC 29/2026 – dispositivo sobre remuneração do proponente | G5: ☐ conferido no texto oficial em ___/___/2026 | I5: Produção / atividade-fim | L5: Pré-produção
A6: Remuneração do proponente – pessoa física ou MEI | B6: 0.3 | C6: VALOR CAPTADO | D6: Proponente pessoa física ou microempreendedor individual. | E6: Continua exigindo serviço efetivo previsto no orçamento. | F6: IN MinC 29/2026 – mesmo dispositivo | G6: ☐ conferido no texto oficial em ___/___/2026 | I6: Cachê – artista solo | J6: =L_CACHE_SOLO | L6: Produção / Execução
A7: Pagamento a um mesmo fornecedor | B7: 0.2 | C7: VALOR CAPTADO | D7: Qualquer fornecedor pago com recurso incentivado. | E7: Há exceções previstas (ex.: intervenções de conservação e restauro de bens culturais). Confira a lista completa no texto oficial. | F7: IN MinC 29/2026 – dispositivo sobre limite por fornecedor | G7: ☐ conferido no texto oficial em ___/___/2026 | I7: Cachê – grupo ou coletivo | J7: =L_CACHE_GRUPO | L7: Pós-produção
A8: Custos de administração | B8: 0.15 | C8: VALOR DO PROJETO | D8: Todos os projetos. | E8: Pagos proporcionalmente às parcelas captadas. 2026: regularização documental de bens de patrimônio passou a ser admitida como custo administrativo; caiu a regra de não concentrar mais de 50% em uma única despesa administrativa. | F8: IN MinC 29/2026 – custos vinculados | G8: ☐ conferido no texto oficial em ___/___/2026 | I8: Cachê – músico de orquestra | J8: =L_CACHE_MUSICO | L8: Divulgação / Comunicação
A9: Acessibilidade, comunicação e divulgação acessíveis | B9: 0.2 | C9: VALOR DO PROJETO | D9: Todos os projetos. | E9: Gastos proporcionalmente à captação. Inclui consultor/coordenador de acessibilidade e equipe treinada para atender PcD durante o evento. | F9: IN MinC 29/2026 – custos vinculados | G9: ☐ conferido no texto oficial em ___/___/2026 | I9: Cachê – maestro / regente | J9: =L_CACHE_MAESTRO | L9: Acessibilidade
A10: Divulgação / comunicação | B10: 0.2 | C10: VALOR DO PROJETO | D10: Todos os projetos. | E10: Inclui assessoria de comunicação, despesas de divulgação e impulsionamento de conteúdo. Materiais e aplicação de marcas passam por aprovação do MinC. | F10: IN MinC 29/2026 – dispositivo sobre divulgação | G10: ☐ conferido no texto oficial em ___/___/2026 | I10: Cachê – palestrante / conferencista | J10: =L_CACHE_PALESTRA | L10: Custos administrativos
A11: Remuneração de captação – percentual | B11: 0.1 | C11: VALOR DO PROJETO | D11: Quem contrata serviço de captação. | E11: Paga proporcionalmente ao valor efetivamente captado. Serviço deve ser prestado ao PROPONENTE; é proibido pagar serviço prestado ao incentivador. | F11: IN MinC 29/2026 – remuneração de captação | G11: ☐ conferido no texto oficial em ___/___/2026 | I11: Remuneração do proponente | L11: Captação de recursos
A12: Remuneração de captação – teto em reais | B12: 150000 | C12: valor absoluto | D12: Idem. | E12: Vale o MENOR entre 10% do valor do projeto e R$ 150.000,00. | F12: IN MinC 29/2026 – remuneração de captação | G12: ☐ conferido no texto oficial em ___/___/2026 | I12: Custos de administração | L12: Encerramento
A13: Cachê – artista solo (por apresentação) | B13: 25000 | C13: por apresentação | D13: Pago com recurso incentivado. | E13: Valores maiores: só com outras fontes ou mediante apreciação da CNIC. | F13: IN MinC 29/2026 – limites de cachê | G13: ☐ conferido no texto oficial em ___/___/2026 | I13: Divulgação / comunicação
A14: Cachê – grupo / coletivo (por apresentação) | B14: 50000 | C14: por apresentação | D14: Idem. | E14: Idem. | F14: IN MinC 29/2026 – limites de cachê | G14: ☐ conferido no texto oficial em ___/___/2026 | I14: Acessibilidade / comunicação e divulgação acessíveis
A15: Cachê – músico de orquestra | B15: 5000 | C15: por apresentação | D15: Idem. | E15: Idem. | F15: IN MinC 29/2026 – limites de cachê | G15: ☐ conferido no texto oficial em ___/___/2026 | I15: Remuneração de captação
A16: Cachê – maestro / regente | B16: 25000 | C16: por apresentação | D16: Idem. | E16: Idem. | F16: IN MinC 29/2026 – limites de cachê | G16: ☐ conferido no texto oficial em ___/___/2026 | I16: Tributos e encargos
A17: Cachê – palestrante / conferencista | B17: 5000 | C17: por participação | D17: Idem. | E17: Idem. | F17: IN MinC 29/2026 – limites de cachê | G17: ☐ conferido no texto oficial em ___/___/2026 | I17: Outros (explique na observação)
A18: Primeiro projeto no Pronac – dispensa de comprovar atuação cultural | B18: 200000 | C18: VALOR DO PROJETO (confira o termo exato) | D18: Proponente que apresenta seu PRIMEIRO projeto ao Pronac. | E18: Dispensa SOMENTE a comprovação de atuação na área cultural. NÃO dispensa cadastro, documentos, orçamento, acessibilidade, democratização nem análise técnica. Acima do limite: precisa comprovar atuação (portfólio no Salic). | F18: IN MinC 29/2026 – dispositivo sobre comprovação de atuação | G18: ☐ conferido no texto oficial em ___/___/2026
A19: Distribuição gratuita promocional – patrocinador (máximo) | B19: 0.1 | C19: total de ingressos/produtos | D19: Projetos com produtos/ingressos. | F19: IN MinC 29/2026 – plano de distribuição | G19: ☐ conferido no texto oficial em ___/___/2026
A20: Distribuição gratuita promocional – proponente/divulgação (máximo) | B20: 0.1 | C20: total de ingressos/produtos | D20: Idem. | F20: IN MinC 29/2026 – plano de distribuição | G20: ☐ conferido no texto oficial em ___/___/2026
A21: Distribuição gratuita social/educativa (mínimo) | B21: 0.1 | C21: total de ingressos/produtos | D21: Idem. | F21: IN MinC 29/2026 – plano de distribuição | G21: ☐ conferido no texto oficial em ___/___/2026
A22: Comercialização a preço popular (mínimo) | B22: 0.2 | C22: total de ingressos/produtos | D22: Idem. | F22: IN MinC 29/2026 – plano de distribuição | G22: ☐ conferido no texto oficial em ___/___/2026
A23: Preço popular – valor máximo | B23: 50 | C23: por ingresso/produto | D23: Idem. | F23: IN MinC 29/2026 – plano de distribuição | G23: ☐ conferido no texto oficial em ___/___/2026
A24: Preço médio do ingresso (máximo) – CONFIRA | B24: 250 | C24: média dos ingressos comercializados | D24: Idem. | E24: Valor encontrado em fontes secundárias. CONFIRA no texto oficial antes de usar. | F24: IN MinC 29/2026 – plano de distribuição | G24: ☐ conferido no texto oficial em ___/___/2026
A25: Pessoa física – projetos ativos | B25: 2 | C25: quantidade | D25: Proponente PF. | E25: Teto global na linha abaixo. | F25: IN MinC 29/2026 – limites por proponente | G25: ☐ conferido no texto oficial em ___/___/2026
A26: Pessoa física – teto global | B26: 500000 | C26: soma dos projetos ativos | D26: Proponente PF. | F26: IN MinC 29/2026 – limites por proponente | G26: ☐ conferido no texto oficial em ___/___/2026
A27: MEI – projetos ativos | B27: 4 | C27: quantidade | D27: Proponente MEI. | F27: IN MinC 29/2026 – limites por proponente | G27: ☐ conferido no texto oficial em ___/___/2026
A28: MEI – teto global | B28: 1500000 | C28: soma dos projetos ativos | D28: Proponente MEI. | F28: IN MinC 29/2026 – limites por proponente | G28: ☐ conferido no texto oficial em ___/___/2026
A29: Demais pessoas jurídicas – projetos ativos | B29: 10 | C29: quantidade | D29: Demais PJ. | E29: 2026: reduzido de 16 para 10; não há mais limite separado para optantes do Simples. | F29: IN MinC 29/2026 – limites por proponente | G29: ☐ conferido no texto oficial em ___/___/2026
A30: Demais pessoas jurídicas – teto global | B30: 15000000 | C30: soma dos projetos ativos | D30: Demais PJ. | E30: Existem regras específicas (ex.: planos anuais, patrimônio, regiões). Confira. | F30: IN MinC 29/2026 – limites por proponente | G30: ☐ conferido no texto oficial em ___/___/2026
A31: Margem de alerta amarelo (a partir de X% do limite) | B31: 0.9 | C31: — | D31: Configuração do kit (não é regra da IN). | E31: Ex.: 0,90 → acima de 90% do limite aparece 🟡 VERIFICAR. | F31: Configuração interna | G31: ☐ conferido no texto oficial em ___/___/2026

Sheet MAPA DO PROJETO
A1: PLANILHA 1 — MAPA DO PROJETO
A2: Preencha a coluna C. A coluna D mostra se o campo está preenchido e quantos caracteres tem. Escreva para o seu projeto — nada de texto genérico copiado.
A4: Campo | B4: Pergunta que o campo responde | C4: SUA RESPOSTA | D4: Status | E4: Nº de caracteres
A5: Nome do projeto | B5: Como o projeto se chama? Curto, claro, sem siglas soltas. | D5: =IF(LEN(TRIM(C5))=0,"🔴 VAZIO",IF(LEN(TRIM(C5))<40,"🟡 MUITO CURTO","🟢 PREENCHIDO")) | E5: =LEN(C5)
A6: Área cultural | B6: Qual a área (ex.: artes cênicas, música, audiovisual, patrimônio, artes visuais, humanidades…)? | D6: =IF(LEN(TRIM(C6))=0,"🔴 VAZIO",IF(LEN(TRIM(C6))<40,"🟡 MUITO CURTO","🟢 PREENCHIDO")) | E6: =LEN(C6)
A7: Segmento | B7: Qual o segmento dentro da área? Ele define enquadramento (art. 18 ou art. 26 da Lei 8.313/1991). | D7: =IF(LEN(TRIM(C7))=0,"🔴 VAZIO",IF(LEN(TRIM(C7))<40,"🟡 MUITO CURTO","🟢 PREENCHIDO")) | E7: =LEN(C7)
A8: Resumo | B8: Em 5 linhas: O QUÊ + ONDE + QUANDO + PARA QUEM + COMO. | D8: =IF(LEN(TRIM(C8))=0,"🔴 VAZIO",IF(LEN(TRIM(C8))<40,"🟡 MUITO CURTO","🟢 PREENCHIDO")) | E8: =LEN(C8)
A9: Objeto (o que será entregue) | B9: Qual é a entrega principal? (ex.: 8 apresentações gratuitas de teatro de rua). | D9: =IF(LEN(TRIM(C9))=0,"🔴 VAZIO",IF(LEN(TRIM(C9))<40,"🟡 MUITO CURTO","🟢 PREENCHIDO")) | E9: =LEN(C9)
A10: Objetivo geral | B10: Qual a grande mudança/resultado cultural que o projeto busca? (1 frase, verbo no infinitivo). | D10: =IF(LEN(TRIM(C10))=0,"🔴 VAZIO",IF(LEN(TRIM(C10))<40,"🟡 MUITO CURTO","🟢 PREENCHIDO")) | E10: =LEN(C10)
A11: Objetivos específicos | B11: 3 a 5 objetivos mensuráveis. Cada um vira META e PRODUTO. | D11: =IF(LEN(TRIM(C11))=0,"🔴 VAZIO",IF(LEN(TRIM(C11))<40,"🟡 MUITO CURTO","🟢 PREENCHIDO")) | E11: =LEN(C11)
A12: Justificativa | B12: Por que este projeto, neste lugar, agora? Qual a lacuna? Qual a relação com a Lei 8.313/1991 (art. 1º)? | D12: =IF(LEN(TRIM(C12))=0,"🔴 VAZIO",IF(LEN(TRIM(C12))<40,"🟡 MUITO CURTO","🟢 PREENCHIDO")) | E12: =LEN(C12)
A13: Metodologia | B13: Como será feito, etapa por etapa? Quem faz o quê? Cada etapa precisa ter despesa no orçamento. | D13: =IF(LEN(TRIM(C13))=0,"🔴 VAZIO",IF(LEN(TRIM(C13))<40,"🟡 MUITO CURTO","🟢 PREENCHIDO")) | E13: =LEN(C13)
A14: Público-alvo | B14: Quem é o público (perfil, faixa etária, território)? Quantas pessoas? | D14: =IF(LEN(TRIM(C14))=0,"🔴 VAZIO",IF(LEN(TRIM(C14))<40,"🟡 MUITO CURTO","🟢 PREENCHIDO")) | E14: =LEN(C14)
A15: Beneficiários | B15: Quem recebe gratuidade, formação, acesso? Escolas, comunidades, instituições? | D15: =IF(LEN(TRIM(C15))=0,"🔴 VAZIO",IF(LEN(TRIM(C15))<40,"🟡 MUITO CURTO","🟢 PREENCHIDO")) | E15: =LEN(C15)
A16: Produtos | B16: Lista dos produtos culturais (apresentação, livro, oficina, exposição, vídeo…) com quantidades. | D16: =IF(LEN(TRIM(C16))=0,"🔴 VAZIO",IF(LEN(TRIM(C16))<40,"🟡 MUITO CURTO","🟢 PREENCHIDO")) | E16: =LEN(C16)
... A24: Outras fontes de recurso | B24: Existe dinheiro/apoio além do incentivo? Está confirmado? Qual despesa ele paga? | D24: =IF(LEN(TRIM(C24))=0,"🔴 VAZIO",IF(LEN(TRIM(C24))<40,"🟡 MUITO CURTO","🟢 PREENCHIDO")) | E24: =LEN(C24)
A26: Campos preenchidos | C26: =COUNTIF(D5:D24,"🟢*")&" de 20"

Sheet ORÇAMENTO
A1: PLANILHA 2 — ORÇAMENTO ANALÍTICO
A2: Colunas A–J: o que vai para o Salic. Colunas K–O (cinza): SUAS conferências. Colunas P–Q: alertas automáticos. Regra: se não consegue explicar por que a despesa existe, não coloque.
A3: Total incentivo (Rouanet) | C3: =SUMIFS(G8:G207,H8:H207,"Incentivo*") | E3: Linhas com alerta 🔴 | G3: =COUNTIF(Q8:Q207,"*🔴*")
A4: Total outras fontes | C4: =SUMIFS(G8:G207,H8:H207,"Outras*") | E4: Linhas com alerta 🟡 | G4: =COUNTIF(Q8:Q207,"*🟡*")
A5: TOTAL GERAL | C5: =C3+C4 | E5: Linhas 🟢 conferidas | G5: =COUNTIF(Q8:Q207,"🟢*")
A7: Etapa | B7: Item | C7: Descrição | D7: Unidade | E7: Quantidade | F7: Valor unitário | G7: Valor total | H7: Fonte | I7: Fornecedor | J7: Observação | K7: Categoria de limite | L7: Pessoa vinculada ao proponente? (cônjuge, companheiro, coligada, sócio em comum) | M7: POR QUE ESSA DESPESA EXISTE? (vínculo com a metodologia) | N7: Preço de mercado conferido? | O7: Esta despesa é paga também por outra fonte? | P7: % do fornecedor sobre o VALOR CAPTADO | Q7: ALERTAS AUTOMÁTICOS
G8: =IF(OR(E8="",F8=""),"",E8*F8) | P8: =IF(OR(I8="",G8="",LEFT(H8,9)<>"Incentivo",VALOR_CAPTADO=0),"",SUMIFS($G$8:$G$207,$I$8:$I$207,I8,$H$8:$H$207,"Incentivo*")/VALOR_CAPTADO) | Q8: =IF(AND(B8="",G8=""),"",IF(IF(AND(B8="",G8=""),"",IF(OR(E8="",F8=""),"🟡 Falta quantidade ou valor. ","")&IF(H8="","🟡 Informe a fonte. ","")&IF(K8="","🟡 Classifique a categoria de limite. ","")&IF(TRIM(M8)="","🔴 Sem justificativa de vínculo: se não explica, não coloque. ","")&IF(N8<>"Sim","🟡 Preço de mercado não conferido. ","")&IF(O8="Sim","🔴 Possível DUPLA COBERTURA: a mesma despesa não pode ser paga duas vezes. ","")&IF(AND(L8="Sim",K8<>"Remuneração do proponente"),"🟡 Pessoa vinculada: este valor SOMA no limite de remuneração do proponente. ","")&IF(P8="","",IF(P8>L_FORNECEDOR,"🔴 Fornecedor acima do limite sobre o valor captado (confira exceções). ",IF(P8>=L_FORNECEDOR*MARGEM,"🟡 Fornecedor perto do limite. ","")))&IF(AND(LEFT(K8,5)="Cachê",F8<>""),IF(F8>IFERROR(VLOOKUP(K8,TAB_CATEGORIAS,2,FALSE),9E+99),"🔴 Cachê acima do limite: só com outras fontes ou apreciação da CNIC. ",""),"")&IF(AND(LEFT(H8,6)="Outras",K8<>""),"🟡 Outras fontes: confirme que o recurso existe e está comprometido. ",""))="","🟢 CONFERIDO",IF(AND(B8="",G8=""),"",IF(OR(E8="",F8=""),"🟡 Falta quantidade ou valor. ","")&IF(H8="","🟡 Informe a fonte. ","")&IF(K8="","🟡 Classifique a categoria de limite. ","")&IF(TRIM(M8)="","🔴 Sem justificativa de vínculo: se não explica, não coloque. ","")&IF(N8<>"Sim","🟡 Preço de mercado não conferido. ","")&IF(O8="Sim","🔴 Possível DUPLA COBERTURA: a mesma despesa não pode ser paga duas vezes. ","")&IF(AND(L8="Sim",K8<>"Remuneração do proponente"),"🟡 Pessoa vinculada: este valor SOMA no limite de remuneração do proponente. ","")&IF(P8="","",IF(P8>L_FORNECEDOR,"🔴 Fornecedor acima do limite sobre o valor captado (confira exceções). ",IF(P8>=L_FORNECEDOR*MARGEM,"🟡 Fornecedor perto do limite. ","")))&IF(AND(LEFT(K8,5)="Cachê",F8<>""),IF(F8>IFERROR(VLOOKUP(K8,TAB_CATEGORIAS,2,FALSE),9E+99),"🔴 Cachê acima do limite: só com outras fontes ou apreciação da CNIC. ",""),"")&IF(AND(LEFT(H8,6)="Outras",K8<>""),"🟡 Outras fontes: confirme que o recurso existe e está comprometido. ",""))))
G9: =IF(OR(E9="",F9=""),"",E9*F9) | P9: =IF(OR(I9="",G9="",LEFT(H9,9)<>"Incentivo",VALOR_CAPTADO=0),"",SUMIFS($G$8:$G$207,$I$8:$I$207,I9,$H$8:$H$207,"Incentivo*")/VALOR_CAPTADO) | Q9: =IF(AND(B9="",G9=""),"",IF(IF(AND(B9="",G9=""),"",IF(OR(E9="",F9=""),"🟡 Falta quantidade ou valor. ","")&IF(H9="","🟡 Informe a fonte. ","")&IF(K9="","🟡 Classifique a categoria de limite. ","")&IF(TRIM(M9)="","🔴 Sem justificativa de vínculo: se não explica, não coloque. ","")&IF(N9<>"Sim","🟡 Preço de mercado não conferido. ","")&IF(O9="Sim","🔴 Possível DUPLA COBERTURA: a mesma despesa não pode ser paga duas vezes. ","")&IF(AND(L9="Sim",K9<>"Remuneração do proponente"),"🟡 Pessoa vinculada: este valor SOMA no limite de remuneração do proponente. ","")&IF(P9="","",IF(P9>L_FORNECEDOR,"🔴 Fornecedor acima do limite sobre o valor captado (confira exceções). ",IF(P9>=L_FORNECEDOR*MARGEM,"🟡 Fornecedor perto do limite. ","")))&IF(AND(LEFT(K9,5)="Cachê",F9<>""),IF(F9>IFERROR(VLOOKUP(K9,TAB_CATEGORIAS,2,FALSE),9E+99),"🔴 Cachê acima do limite: só com outras fontes ou apreciação da CNIC. ",""),"")&IF(AND(LEFT(H9,6)="Outras",K9<>""),"🟡 Outras fontes: confirme que o recurso existe e está comprometido. ",""))="","🟢 CONFERIDO",IF(AND(B9="",G9=""),"",IF(OR(E9="",F9=""),"🟡 Falta quantidade ou valor. ","")&IF(H9="","🟡 Informe a fonte. ","")&IF(K9="","🟡 Classifique a categoria de limite. ","")&IF(TRIM(M9)="","🔴 Sem justificativa de vínculo: se não explica, não coloque. ","")&IF(N9<>"Sim","🟡 Preço de mercado não conferido. ","")&IF(O9="Sim","🔴 Possível DUPLA COBERTURA: a mesma despesa não pode ser paga duas vezes. ","")&IF(AND(L9="Sim",K9<>"Remuneração do proponente"),"🟡 Pessoa vinculada: este valor SOMA no limite de remuneração do proponente. ","")&IF(P9="","",IF(P9>L_FORNECEDOR,"🔴 Fornecedor acima do limite sobre o valor captado (confira exceções). ",IF(P9>=L_FORNECEDOR*MARGEM,"🟡 Fornecedor perto do limite. ","")))&IF(AND(LEFT(K9,5)="Cachê",F9<>""),IF(F9>IFERROR(VLOOKUP(K9,TAB_CATEGORIAS,2,FALSE),9E+99),"🔴 Cachê acima do limite: só com outras fontes ou apreciação da CNIC. ",""),"")&IF(AND(LEFT(H9,6)="Outras",K9<>""),"🟡 Outras fontes: confirme que o recurso existe e está comprometido. ",""))))
G10: =IF(OR(E10="",F10=""),"",E10*F10) | P10: =IF(OR(I10="",G10="",LEFT(H10,9)<>"Incentivo",VALOR_CAPTADO=0),"",SUMIFS($G$8:$G$207,$I$8:$I$207,I10,$H$8:$H$207,"Incentivo*")/VALOR_CAPTADO) | Q10: =IF(AND(B10="",G10=""),"",IF(IF(AND(B10="",G10=""),"",IF(OR(E10="",F10=""),"🟡 Falta quantidade ou valor. ","")&IF(H10="","🟡 Informe a fonte. ","")&IF(K10="","🟡 Classifique a categoria de limite. ","")&IF(TRIM(M10)="","🔴 Sem justificativa de vínculo: se não explica, não coloque. ","")&IF(N10<>"Sim","🟡 Preço de mercado não conferido. ","")&IF(O10="Sim","🔴 Possível DUPLA COBERTURA: a mesma despesa não pode ser paga duas vezes. ","")&IF(AND(L10="Sim",K10<>"Remuneração do proponente"),"🟡 Pessoa vinculada: este valor SOMA no limite de remuneração do proponente. ","")&IF(P10="","",IF(P10>L_FORNECEDOR,"🔴 Fornecedor acima do limite sobre o valor captado (confira exceções). ",IF(P10>=L_FORNECEDOR*MARGEM,"🟡 Fornecedor perto do limite. ","")))&IF(AND(LEFT(K10,5)="Cachê",F10<>""),IF(F10>IFERROR(VLOOKUP(K10,TAB_CATEGORIAS,2,FALSE),9E+99),"🔴 Cachê acima do limite: só com outras fontes ou apreciação da CNIC. ",""),"")&IF(AND(LEFT(H10,6)="Outras",K10<>""),"🟡 Outras fontes: confirme que o recurso existe e está comprometido. ",""))="","🟢 CONFERIDO",IF(AND(B10="",G10=""),"",IF(OR(E10="",F10=""),"🟡 Falta quantidade ou valor. ","")&IF(H10="","🟡 Informe a fonte. ","")&IF(K10="","🟡 Classifique a categoria de limite. ","")&IF(TRIM(M10)="","🔴 Sem justificativa de vínculo: se não explica, não coloque. ","")&IF(N10<>"Sim","🟡 Preço de mercado não conferido. ","")&IF(O10="Sim","🔴 Possível DUPLA COBERTURA: a mesma despesa não pode ser paga duas vezes. ","")&IF(AND(L10="Sim",K10<>"Remuneração do proponente"),"🟡 Pessoa vinculada: este valor SOMA no limite de remuneração do proponente. ","")&IF(P10="","",IF(P10>L_FORNECEDOR,"🔴 Fornecedor acima do limite sobre o valor captado (confira exceções). ",IF(P10>=L_FORNECEDOR*MARGEM,"🟡 Fornecedor perto do limite. ","")))&IF(AND(LEFT(K10,5)="Cachê",F10<>""),IF(F10>IFERROR(VLOOKUP(K10,TAB_CATEGORIAS,2,FALSE),9E+99),"🔴 Cachê acima do limite: só com outras fontes ou apreciação da CNIC. ",""),"")&IF(AND(LEFT(H10,6)="Outras",K10<>""),"🟡 Outras fontes: confirme que o recurso existe e está comprometido. ",""))))
G11: =IF(OR(E11="",F11=""),"",E11*F11) | P11: =IF(OR(I11="",G11="",LEFT(H11,9)<>"Incentivo",VALOR_CAPTADO=0),"",SUMIFS($G$8:$G$207,$I$8:$I$207,I11,$H$8:$H$207,"Incentivo*")/VALOR_CAPTADO) | Q11: =IF(AND(B11="",G11=""),"",IF(IF(AND(B11="",G11=""),"",IF(OR(E11="",F11=""),"🟡 Falta quantidade ou valor. ","")&IF(H11="","🟡 Informe a fonte. ","")&IF(K11="","🟡 Classifique a categoria de limite. ","")&IF(TRIM(M11)="","🔴 Sem justificativa de vínculo: se não explica, não coloque. ","")&IF(N11<>"Sim","🟡 Preço de mercado não conferido. ","")&IF(O11="Sim","🔴 Possível DUPLA COBERTURA: a mesma despesa não pode ser paga duas vezes. ","")&IF(AND(L11="Sim",K11<>"Remuneração do proponente"),"🟡 Pessoa vinculada: este valor SOMA no limite de remuneração do proponente. ","")&IF(P11="","",IF(P11>L_FORNECEDOR,"🔴 Fornecedor acima do limite sobre o valor captado (confira exceções). ",IF(P11>=L_FORNECEDOR*MARGEM,"🟡 Fornecedor perto do limite. ","")))&IF(AND(LEFT(K11,5)="Cachê",F11<>""),IF(F11>IFERROR(VLOOKUP(K11,TAB_CATEGORIAS,2,FALSE),9E+99),"🔴 Cachê acima do limite: só com outras fontes ou apreciação da CNIC. ",""),"")&IF(AND(LEFT(H11,6)="Outras",K11<>""),"🟡 Outras fontes: confirme que o recurso existe e está comprometido. ",""))="","🟢 CONFERIDO",IF(AND(B11="",G11=""),"",IF(OR(E11="",F11=""),"🟡 Falta quantidade ou valor. ","")&IF(H11="","🟡 Informe a fonte. ","")&IF(K11="","🟡 Classifique a categoria de limite. ","")&IF(TRIM(M11)="","🔴 Sem justificativa de vínculo: se não explica, não coloque. ","")&IF(N11<>"Sim","🟡 Preço de mercado não conferido. ","")&IF(O11="Sim","🔴 Possível DUPLA COBERTURA: a mesma despesa não pode ser paga duas vezes. ","")&IF(AND(L11="Sim",K11<>"Remuneração do proponente"),"🟡 Pessoa vinculada: este valor SOMA no limite de remuneração do proponente. ","")&IF(P11="","",IF(P11>L_FORNECEDOR,"🔴 Fornecedor acima do limite sobre o valor captado (confira exceções). ",IF(P11>=L_FORNECEDOR*MARGEM,"🟡 Fornecedor perto do limite. ","")))&IF(AND(LEFT(K11,5)="Cachê",F11<>""),IF(F11>IFERROR(VLOOKUP(K11,TAB_CATEGORIAS,2,FALSE),9E+99),"🔴 Cachê acima do limite: só com outras fontes ou apreciação da CNIC. ",""),"")&IF(AND(LEFT(H11,6)="Outras",K11<>""),"🟡 Outras fontes: confirme que o recurso existe e está comprometido. ",""))))
G12: =IF(OR(E12="",F12=""),"",E12*F12) | P12: =IF(OR(I12="",G12="",LEFT(H12,9)<>"Incentivo",VALOR_CAPTADO=0),"",SUMIFS($G$8:$G$207,$I$8:$I$207,I12,$H$8:$H$207,"Incentivo*")/VALOR_CAPTADO) | Q12: =IF(AND(B12="",G12=""),"",IF(IF(AND(B12="",G12=""),"",IF(OR(E12="",F12=""),"🟡 Falta quantidade ou valor. ","")&IF(H12="","🟡 Informe a fonte. ","")&IF(K12="","🟡 Classifique a categoria de limite. ","")&IF(TRIM(M12)="","🔴 Sem justificativa de vínculo: se não explica, não coloque. ","")&IF(N12<>"Sim","🟡 Preço de mercado não conferido. ","")&IF(O12="Sim","🔴 Possível DUPLA COBERTURA: a mesma despesa não pode ser paga duas vezes. ","")&IF(AND(L12="Sim",K12<>"Remuneração do proponente"),"🟡 Pessoa vinculada: este valor SOMA no limite de remuneração do proponente. ","")&IF(P12="","",IF(P12>L_FORNECEDOR,"🔴 Fornecedor acima do limite sobre o valor captado (confira exceções). ",IF(P12>=L_FORNECEDOR*MARGEM,"🟡 Fornecedor perto do limite. ","")))&IF(AND(LEFT(K12,5)="Cachê",F12<>""),IF(F12>IFERROR(VLOOKUP(K12,TAB_CATEGORIAS,2,FALSE),9E+99),"🔴 Cachê acima do limite: só com outras fontes ou apreciação da CNIC. ",""),"")&IF(AND(LEFT(H12,6)="Outras",K12<>""),"🟡 Outras fontes: confirme que o recurso existe e está comprometido. ",""))="","🟢 CONFERIDO",IF(AND(B12="",G12=""),"",IF(OR(E12="",F12=""),"🟡 Falta quantidade ou valor. ","")&IF(H12="","🟡 Informe a fonte. ","")&IF(K12="","🟡 Classifique a categoria de limite. ","")&IF(TRIM(M12)="","🔴 Sem justificativa de vínculo: se não explica, não coloque. ","")&IF(N12<>"Sim","🟡 Preço de mercado não conferido. ","")&IF(O12="Sim","🔴 Possível DUPLA COBERTURA: a mesma despesa não pode ser paga duas vezes. ","")&IF(AND(L12="Sim",K12<>"Remuneração do proponente"),"🟡 Pessoa vinculada: este valor SOMA no limite de remuneração do proponente. ","")&IF(P12="","",IF(P12>L_FORNECEDOR,"🔴 Fornecedor acima do limite sobre o valor captado (confira exceções). ",IF(P12>=L_FORNECEDOR*MARGEM,"🟡 Fornecedor perto do limite. ","")))&IF(AND(LEFT(K12,5)="Cachê",F12<>""),IF(F12>IFERROR(VLOOKUP(K12,TAB_CATEGORIAS,2,FALSE),9E+99),"🔴 Cachê acima do limite: só com outras fontes ou apreciação da CNIC. ",""),"")&IF(AND(LEFT(H12,6)="Outras",K12<>""),"🟡 Outras fontes: confirme que o recurso existe e está comprometido. ",""))))
G13: =IF(OR(E13="",F13=""),"",E13*F13) | P13: =IF(OR(I13="",G13="",LEFT(H13,9)<>"Incentivo",VALOR_CAPTADO=0),"",SUMIFS($G$8:$G$207,$I$8:$I$207,I13,$H$8:$H$207,"Incentivo*")/VALOR_CAPTADO) | Q13: =IF(AND(B13="",G13=""),"",IF(IF(AND(B13="",G13=""),"",IF(OR(E13="",F13=""),"🟡 Falta quantidade ou valor. ","")&IF(H13="","🟡 Informe a fonte. ","")&IF(K13="","🟡 Classifique a categoria de limite. ","")&IF(TRIM(M13)="","🔴 Sem justificativa de vínculo: se não explica, não coloque. ","")&IF(N13<>"Sim","🟡 Preço de mercado não conferido. ","")&IF(O13="Sim","🔴 Possível DUPLA COBERTURA: a mesma despesa não pode ser paga duas vezes. ","")&IF(AND(L13="Sim",K13<>"Remuneração do proponente"),"🟡 Pessoa vinculada: este valor SOMA no limite de remuneração do proponente. ","")&IF(P13="","",IF(P13>L_FORNECEDOR,"🔴 Fornecedor acima do limite sobre o valor captado (confira exceções). ",IF(P13>=L_FORNECEDOR*MARGEM,"🟡 Fornecedor perto do limite. ","")))&IF(AND(LEFT(K13,5)="Cachê",F13<>""),IF(F13>IFERROR(VLOOKUP(K13,TAB_CATEGORIAS,2,FALSE),9E+99),"🔴 Cachê acima do limite: só com outras fontes ou apreciação da CNIC. ",""),"")&IF(AND(LEFT(H13,6)="Outras",K13<>""),"🟡 Outras fontes: confirme que o recurso existe e está comprometido. ",""))="","🟢 CONFERIDO",IF(AND(B13="",G13=""),"",IF(OR(E13="",F13=""),"🟡 Falta quantidade ou valor. ","")&IF(H13="","🟡 Informe a fonte. ","")&IF(K13="","🟡 Classifique a categoria de limite. ","")&IF(TRIM(M13)="","🔴 Sem justificativa de vínculo: se não explica, não coloque. ","")&IF(N13<>"Sim","🟡 Preço de mercado não conferido. ","")&IF(O13="Sim","🔴 Possível DUPLA COBERTURA: a mesma despesa não pode ser paga duas vezes. ","")&IF(AND(L13="Sim",K13<>"Remuneração do proponente"),"🟡 Pessoa vinculada: este valor SOMA no limite de remuneração do proponente. ","")&IF(P13="","",IF(P13>L_FORNECEDOR,"🔴 Fornecedor acima do limite sobre o valor captado (confira exceções). ",IF(P13>=L_FORNECEDOR*MARGEM,"🟡 Fornecedor perto do limite. ","")))&IF(AND(LEFT(K13,5)="Cachê",F13<>""),IF(F13>IFERROR(VLOOKUP(K13,TAB_CATEGORIAS,2,FALSE),9E+99),"🔴 Cachê acima do limite: só com outras fontes ou apreciação da CNIC. ",""),"")&IF(AND(LEFT(H13,6)="Outras",K13<>""),"🟡 Outras fontes: confirme que o recurso existe e está comprometido. ",""))))
G14: =IF(OR(E14="",F14=""),"",E14*F14) | P14: =IF(OR(I14="",G14="",LEFT(H14,9)<>"Incentivo",VALOR_CAPTADO=0),"",SUMIFS($G$8:$G$207,$I$8:$I$207,I14,$H$8:$H$207,"Incentivo*")/VALOR_CAPTADO) | Q14: =IF(AND(B14="",G14=""),"",IF(IF(AND(B14="",G14=""),"",IF(OR(E14="",F14=""),"🟡 Falta quantidade ou valor. ","")&IF(H14="","🟡 Informe a fonte. ","")&IF(K14="","🟡 Classifique a categoria de limite. ","")&IF(TRIM(M14)="","🔴 Sem justificativa de vínculo: se não explica, não coloque. ","")&IF(N14<>"Sim","🟡 Preço de mercado não conferido. ","")&IF(O14="Sim","🔴 Possível DUPLA COBERTURA: a mesma despesa não pode ser paga duas vezes. ","")&IF(AND(L14="Sim",K14<>"Remuneração do proponente"),"🟡 Pessoa vinculada: este valor SOMA no limite de remuneração do proponente. ","")&IF(P14="","",IF(P14>L_FORNECEDOR,"🔴 Fornecedor acima do limite sobre o valor captado (confira exceções). ",IF(P14>=L_FORNECEDOR*MARGEM,"🟡 Fornecedor perto do limite. ","")))&IF(AND(LEFT(K14,5)="Cachê",F14<>""),IF(F14>IFERROR(VLOOKUP(K14,TAB_CATEGORIAS,2,FALSE),9E+99),"🔴 Cachê acima do limite: só com outras fontes ou apreciação da CNIC. ",""),"")&IF(AND(LEFT(H14,6)="Outras",K14<>""),"🟡 Outras fontes: confirme que o recurso existe e está comprometido. ",""))="","🟢 CONFERIDO",IF(AND(B14="",G14=""),"",IF(OR(E14="",F14=""),"🟡 Falta quantidade ou valor. ","")&IF(H14="","🟡 Informe a fonte. ","")&IF(K14="","🟡 Classifique a categoria de limite. ","")&IF(TRIM(M14)="","🔴 Sem justificativa de vínculo: se não explica, não coloque. ","")&IF(N14<>"Sim","🟡 Preço de mercado não conferido. ","")&IF(O14="Sim","🔴 Possível DUPLA COBERTURA: a mesma despesa não pode ser paga duas vezes. ","")&IF(AND(L14="Sim",K14<>"Remuneração do proponente"),"🟡 Pessoa vinculada: este valor SOMA no limite de remuneração do proponente. ","")&IF(P14="","",IF(P14>L_FORNECEDOR,"🔴 Fornecedor acima do limite sobre o valor captado (confira exceções). ",IF(P14>=L_FORNECEDOR*MARGEM,"🟡 Fornecedor perto do limite. ","")))&IF(AND(LEFT(K14,5)="Cachê",F14<>""),IF(F14>IFERROR(VLOOKUP(K14,TAB_CATEGORIAS,2,FALSE),9E+99),"🔴 Cachê acima do limite: só com outras fontes ou apreciação da CNIC. ",""),"")&IF(AND(LEFT(H14,6)="Outras",K14<>""),"🟡 Outras fontes: confirme que o recurso existe e está comprometido. ",""))))
G15: =IF(OR(E15="",F15=""),"",E15*F15) | P15: =IF(OR(I15="",G15="",LEFT(H15,9)<>"Incentivo",VALOR_CAPTADO=0),"",SUMIFS($G$8:$G$207,$I$8:$I$207,I15,$H$8:$H$207,"Incentivo*")/VALOR_CAPTADO) | Q15: =IF(AND(B15="",G15=""),"",IF(IF(AND(B15="",G15=""),"",IF(OR(E15="",F15=""),"🟡 Falta quantidade ou valor. ","")&IF(H15="","🟡 Informe a fonte. ","")&IF(K15="","🟡 Classifique a categoria de limite. ","")&IF(TRIM(M15)="","🔴 Sem justificativa de vínculo: se não explica, não coloque. ","")&IF(N15<>"Sim","🟡 Preço de mercado não conferido. ","")&IF(O15="Sim","🔴 Possível DUPLA COBERTURA: a mesma despesa não pode ser paga duas vezes. ","")&IF(AND(L15="Sim",K15<>"Remuneração do proponente"),"🟡 Pessoa vinculada: este valor SOMA no limite de remuneração do proponente. ","")&IF(P15="","",IF(P15>L_FORNECEDOR,"🔴 Fornecedor acima do limite sobre o valor captado (confira exceções). ",IF(P15>=L_FORNECEDOR*MARGEM,"🟡 Fornecedor perto do limite. ","")))&IF(AND(LEFT(K15,5)="Cachê",F15<>""),IF(F15>IFERROR(VLOOKUP(K15,TAB_CATEGORIAS,2,FALSE),9E+99),"🔴 Cachê acima do limite: só com outras fontes ou apreciação da CNIC. ",""),"")&IF(AND(LEFT(H15,6)="Outras",K15<>""),"🟡 Outras fontes: confirme que o recurso existe e está comprometido. ",""))="","🟢 CONFERIDO",IF(AND(B15="",G15=""),"",IF(OR(E15="",F15=""),"🟡 Falta quantidade ou valor. ","")&IF(H15="","🟡 Informe a fonte. ","")&IF(K15="","🟡 Classifique a categoria de limite. ","")&IF(TRIM(M15)="","🔴 Sem justificativa de vínculo: se não explica, não coloque. ","")&IF(N15<>"Sim","🟡 Preço de mercado não conferido. ","")&IF(O15="Sim","🔴 Possível DUPLA COBERTURA: a mesma despesa não pode ser paga duas vezes. ","")&IF(AND(L15="Sim",K15<>"Remuneração do proponente"),"🟡 Pessoa vinculada: este valor SOMA no limite de remuneração do proponente. ","")&IF(P15="","",IF(P15>L_FORNECEDOR,"🔴 Fornecedor acima do limite sobre o valor captado (confira exceções). ",IF(P15>=L_FORNECEDOR*MARGEM,"🟡 Fornecedor perto do limite. ","")))&IF(AND(LEFT(K15,5)="Cachê",F15<>""),IF(F15>IFERROR(VLOOKUP(K15,TAB_CATEGORIAS,2,FALSE),9E+99),"🔴 Cachê acima do limite: só com outras fontes ou apreciação da CNIC. ",""),"")&IF(AND(LEFT(H15,6)="Outras",K15<>""),"🟡 Outras fontes: confirme que o recurso existe e está comprometido. ",""))))
G16: =IF(OR(E16="",F16=""),"",E16*F16) | P16: =IF(OR(I16="",G16="",LEFT(H16,9)<>"Incentivo",VALOR_CAPTADO=0),"",SUMIFS($G$8:$G$207,$I$8:$I$207,I16,$H$8:$H$207,"Incentivo*")/VALOR_CAPTADO) | Q16: =IF(AND(B16="",G16=""),"",IF(IF(AND(B16="",G16=""),"",IF(OR(E16="",F16=""),"🟡 Falta quantidade ou valor. ","")&IF(H16="","🟡 Informe a fonte. ","")&IF(K16="","🟡 Classifique a categoria de limite. ","")&IF(TRIM(M16)="","🔴 Sem justificativa de vínculo: se não explica, não coloque. ","")&IF(N16<>"Sim","🟡 Preço de mercado não conferido. ","")&IF(O16="Sim","🔴 Possível DUPLA COBERTURA: a mesma despesa não pode ser paga duas vezes. ","")&IF(AND(L16="Sim",K16<>"Remuneração do proponente"),"🟡 Pessoa vinculada: este valor SOMA no limite de remuneração do proponente. ","")&IF(P16="","",IF(P16>L_FORNECEDOR,"🔴 Fornecedor acima do limite sobre o valor captado (confira exceções). ",IF(P16>=L_FORNECEDOR*MARGEM,"🟡 Fornecedor perto do limite. ","")))&IF(AND(LEFT(K16,5)="Cachê",F16<>""),IF(F16>IFERROR(VLOOKUP(K16,TAB_CATEGORIAS,2,FALSE),9E+99),"🔴 Cachê acima do limite: só com outras fontes ou apreciação da CNIC. ",""),"")&IF(AND(LEFT(H16,6)="Outras",K16<>""),"🟡 Outras fontes: confirme que o recurso existe e está comprometido. ",""))="","🟢 CONFERIDO",IF(AND(B16="",G16=""),"",IF(OR(E16="",F16=""),"🟡 Falta quantidade ou valor. ","")&IF(H16="","🟡 Informe a fonte. ","")&IF(K16="","🟡 Classifique a categoria de limite. ","")&IF(TRIM(M16)="","🔴 Sem justificativa de vínculo: se não explica, não coloque. ","")&IF(N16<>"Sim","🟡 Preço de mercado não conferido. ","")&IF(O16="Sim","🔴 Possível DUPLA COBERTURA: a mesma despesa não pode ser paga duas vezes. ","")&IF(AND(L16="Sim",K16<>"Remuneração do proponente"),"🟡 Pessoa vinculada: este valor SOMA no limite de remuneração do proponente. ","")&IF(P16="","",IF(P16>L_FORNECEDOR,"🔴 Fornecedor acima do limite sobre o valor captado (confira exceções). ",IF(P16>=L_FORNECEDOR*MARGEM,"🟡 Fornecedor perto do limite. ","")))&IF(AND(LEFT(K16,5)="Cachê",F16<>""),IF(F16>IFERROR(VLOOKUP(K16,TAB_CATEGORIAS,2,FALSE),9E+99),"🔴 Cachê acima do limite: só com outras fontes ou apreciação da CNIC. ",""),"")&IF(AND(LEFT(H16,6)="Outras",K16<>""),"🟡 Outras fontes: confirme que o recurso existe e está comprometido. ",""))))
G17: =IF(OR(E17="",F17=""),"",E17*F17) | P17: =IF(OR(I17="",G17="",LEFT(H17,9)<>"Incentivo",VALOR_CAPTADO=0),"",SUMIFS($G$8:$G$207,$I$8:$I$207,I17,$H$8:$H$207,"Incentivo*")/VALOR_CAPTADO) | Q17: =IF(AND(B17="",G17=""),"",IF(IF(AND(B17="",G17=""),"",IF(OR(E17="",F17=""),"🟡 Falta quantidade ou valor. ","")&IF(H17="","🟡 Informe a fonte. ","")&IF(K17="","🟡 Classifique a categoria de limite. ","")&IF(TRIM(M17)="","🔴 Sem justificativa de vínculo: se não explica, não coloque. ","")&IF(N17<>"Sim","🟡 Preço de mercado não conferido. ","")&IF(O17="Sim","🔴 Possível DUPLA COBERTURA: a mesma despesa não pode ser paga duas vezes. ","")&IF(AND(L17="Sim",K17<>"Remuneração do proponente"),"🟡 Pessoa vinculada: este valor SOMA no limite de remuneração do proponente. ","")&IF(P17="","",IF(P17>L_FORNECEDOR,"🔴 Fornecedor acima do limite sobre o valor captado (confira exceções). ",IF(P17>=L_FORNECEDOR*MARGEM,"🟡 Fornecedor perto do limite. ","")))&IF(AND(LEFT(K17,5)="Cachê",F17<>""),IF(F17>IFERROR(VLOOKUP(K17,TAB_CATEGORIAS,2,FALSE),9E+99),"🔴 Cachê acima do limite: só com outras fontes ou apreciação da CNIC. ",""),"")&IF(AND(LEFT(H17,6)="Outras",K17<>""),"🟡 Outras fontes: confirme que o recurso existe e está comprometido. ",""))="","🟢 CONFERIDO",IF(AND(B17="",G17=""),"",IF(OR(E17="",F17=""),"🟡 Falta quantidade ou valor. ","")&IF(H17="","🟡 Informe a fonte. ","")&IF(K17="","🟡 Classifique a categoria de limite. ","")&IF(TRIM(M17)="","🔴 Sem justificativa de vínculo: se não explica, não coloque. ","")&IF(N17<>"Sim","🟡 Preço de mercado não conferido. ","")&IF(O17="Sim","🔴 Possível DUPLA COBERTURA: a mesma despesa não pode ser paga duas vezes. ","")&IF(AND(L17="Sim",K17<>"Remuneração do proponente"),"🟡 Pessoa vinculada: este valor SOMA no limite de remuneração do proponente. ","")&IF(P17="","",IF(P17>L_FORNECEDOR,"🔴 Fornecedor acima do limite sobre o valor captado (confira exceções). ",IF(P17>=L_FORNECEDOR*MARGEM,"🟡 Fornecedor perto do limite. ","")))&IF(AND(LEFT(K17,5)="Cachê",F17<>""),IF(F17>IFERROR(VLOOKUP(K17,TAB_CATEGORIAS,2,FALSE),9E+99),"🔴 Cachê acima do limite: só com outras fontes ou apreciação da CNIC. ",""),"")&IF(AND(LEFT(H17,6)="Outras",K17<>""),"🟡 Outras fontes: confirme que o recurso existe e está comprometido. ",""))))
G18: =IF(OR(E18="",F18=""),"",E18*F18) | P18: =IF(OR(I18="",G18="",LEFT(H18,9)<>"Incentivo",VALOR_CAPTADO=0),"",SUMIFS($G$8:$G$207,$I$8:$I$207,I18,$H$8:$H$207,"Incentivo*")/VALOR_CAPTADO) | Q18: =IF(AND(B18="",G18=""),"",IF(IF(AND(B18="",G18=""),"",IF(OR(E18="",F18=""),"🟡 Falta quantidade ou valor. ","")&IF(H18="","🟡 Informe a fonte. ","")&IF(K18="","🟡 Classifique a categoria de limite. ","")&IF(TRIM(M18)="","🔴 Sem justificativa de vínculo: se não explica, não coloque. ","")&IF(N18<>"Sim","🟡 Preço de mercado não conferido. ","")&IF(O18="Sim","🔴 Possível DUPLA COBERTURA: a mesma despesa não pode ser paga duas vezes. ","")&IF(AND(L18="Sim",K18<>"Remuneração do proponente"),"🟡 Pessoa vinculada: este valor SOMA no limite de remuneração do proponente. ","")&IF(P18="","",IF(P18>L_FORNECEDOR,"🔴 Fornecedor acima do limite sobre o valor captado (confira exceções). ",IF(P18>=L_FORNECEDOR*MARGEM,"🟡 Fornecedor perto do limite. ","")))&IF(AND(LEFT(K18,5)="Cachê",F18<>""),IF(F18>IFERROR(VLOOKUP(K18,TAB_CATEGORIAS,2,FALSE),9E+99),"🔴 Cachê acima do limite: só com outras fontes ou apreciação da CNIC. ",""),"")&IF(AND(LEFT(H18,6)="Outras",K18<>""),"🟡 Outras fontes: confirme que o recurso existe e está comprometido. ",""))="","🟢 CONFERIDO",IF(AND(B18="",G18=""),"",IF(OR(E18="",F18=""),"🟡 Falta quantidade ou valor. ","")&IF(H18="","🟡 Informe a fonte. ","")&IF(K18="","🟡 Classifique a categoria de limite. ","")&IF(TRIM(M18)="","🔴 Sem justificativa de vínculo: se não explica, não coloque. ","")&IF(N18<>"Sim","🟡 Preço de mercado não conferido. ","")&IF(O18="Sim","🔴 Possível DUPLA COBERTURA: a mesma despesa não pode ser paga duas vezes. ","")&IF(AND(L18="Sim",K18<>"Remuneração do proponente"),"🟡 Pessoa vinculada: este valor SOMA no limite de remuneração do proponente. ","")&IF(P18="","",IF(P18>L_FORNECEDOR,"🔴 Fornecedor acima do limite sobre o valor captado (confira exceções). ",IF(P18>=L_FORNECEDOR*MARGEM,"🟡 Fornecedor perto do limite. ","")))&IF(AND(LEFT(K18,5)="Cachê",F18<>""),IF(F18>IFERROR(VLOOKUP(K18,TAB_CATEGORIAS,2,FALSE),9E+99),"🔴 Cachê acima do limite: só com outras fontes ou apreciação da CNIC. ",""),"")&IF(AND(LEFT(H18,6)="Outras",K18<>""),"🟡 Outras fontes: confirme que o recurso existe e está comprometido. ",""))))
G19: =IF(OR(E19="",F19=""),"",E19*F19) | P19: =IF(OR(I19="",G19="",LEFT(H19,9)<>"Incentivo",VALOR_CAPTADO=0),"",SUMIFS($G$8:$G$207,$I$8:$I$207,I19,$H$8:$H$207,"Incentivo*")/VALOR_CAPTADO) | Q19: =IF(AND(B19="",G19=""),"",IF(IF(AND(B19="",G19=""),"",IF(OR(E19="",F19=""),"🟡 Falta quantidade ou valor. ","")&IF(H19="","🟡 Informe a fonte. ","")&IF(K19="","🟡 Classifique a categoria de limite. ","")&IF(TRIM(M19)="","🔴 Sem justificativa de vínculo: se não explica, não coloque. ","")&IF(N19<>"Sim","🟡 Preço de mercado não conferido. ","")&IF(O19="Sim","🔴 Possível DUPLA COBERTURA: a mesma despesa não pode ser paga duas vezes. ","")&IF(AND(L19="Sim",K19<>"Remuneração do proponente"),"🟡 Pessoa vinculada: este valor SOMA no limite de remuneração do proponente. ","")&IF(P19="","",IF(P19>L_FORNECEDOR,"🔴 Fornecedor acima do limite sobre o valor captado (confira exceções). ",IF(P19>=L_FORNECEDOR*MARGEM,"🟡 Fornecedor perto do limite. ","")))&IF(AND(LEFT(K19,5)="Cachê",F19<>""),IF(F19>IFERROR(VLOOKUP(K19,TAB_CATEGORIAS,2,FALSE),9E+99),"🔴 Cachê acima do limite: só com outras fontes ou apreciação da CNIC. ",""),"")&IF(AND(LEFT(H19,6)="Outras",K19<>""),"🟡 Outras fontes: confirme que o recurso existe e está comprometido. ",""))="","🟢 CONFERIDO",IF(AND(B19="",G19=""),"",IF(OR(E19="",F19=""),"🟡 Falta quantidade ou valor. ","")&IF(H19="","🟡 Informe a fonte. ","")&IF(K19="","🟡 Classifique a categoria de limite. ","")&IF(TRIM(M19)="","🔴 Sem justificativa de vínculo: se não explica, não coloque. ","")&IF(N19<>"Sim","🟡 Preço de mercado não conferido. ","")&IF(O19="Sim","🔴 Possível DUPLA COBERTURA: a mesma despesa não pode ser paga duas vezes. ","")&IF(AND(L19="Sim",K19<>"Remuneração do proponente"),"🟡 Pessoa vinculada: este valor SOMA no limite de remuneração do proponente. ","")&IF(P19="","",IF(P19>L_FORNECEDOR,"🔴 Fornecedor acima do limite sobre o valor captado (confira exceções). ",IF(P19>=L_FORNECEDOR*MARGEM,"🟡 Fornecedor perto do limite. ","")))&IF(AND(LEFT(K19,5)="Cachê",F19<>""),IF(F19>IFERROR(VLOOKUP(K19,TAB_CATEGORIAS,2,FALSE),9E+99),"🔴 Cachê acima do limite: só com outras fontes ou apreciação da CNIC. ",""),"")&IF(AND(LEFT(H19,6)="Outras",K19<>""),"🟡 Outras fontes: confirme que o recurso existe e está comprometido. ",""))))
... G207: =IF(OR(E207="",F207=""),"",E207*F207) | P207: =IF(OR(I207="",G207="",LEFT(H207,9)<>"Incentivo",VALOR_CAPTADO=0),"",SUMIFS($G$8:$G$207,$I$8:$I$207,I207,$H$8:$H$207,"Incentivo*")/VALOR_CAPTADO) | Q207: =IF(AND(B207="",G207=""),"",IF(IF(AND(B207="",G207=""),"",IF(OR(E207="",F207=""),"🟡 Falta quantidade ou valor. ","")&IF(H207="","🟡 Informe a fonte. ","")&IF(K207="","🟡 Classifique a categoria de limite. ","")&IF(TRIM(M207)="","🔴 Sem justificativa de vínculo: se não explica, não coloque. ","")&IF(N207<>"Sim","🟡 Preço de mercado não conferido. ","")&IF(O207="Sim","🔴 Possível DUPLA COBERTURA: a mesma despesa não pode ser paga duas vezes. ","")&IF(AND(L207="Sim",K207<>"Remuneração do proponente"),"🟡 Pessoa vinculada: este valor SOMA no limite de remuneração do proponente. ","")&IF(P207="","",IF(P207>L_FORNECEDOR,"🔴 Fornecedor acima do limite sobre o valor captado (confira exceções). ",IF(P207>=L_FORNECEDOR*MARGEM,"🟡 Fornecedor perto do limite. ","")))&IF(AND(LEFT(K207,5)="Cachê",F207<>""),IF(F207>IFERROR(VLOOKUP(K207,TAB_CATEGORIAS,2,FALSE),9E+99),"🔴 Cachê acima do limite: só com outras fontes ou apreciação da CNIC. ",""),"")&IF(AND(LEFT(H207,6)="Outras",K207<>""),"🟡 Outras fontes: confirme que o recurso existe e está comprometido. ",""))="","🟢 CONFERIDO",IF(AND(B207="",G207=""),"",IF(OR(E207="",F207=""),"🟡 Falta quantidade ou valor. ","")&IF(H207="","🟡 Informe a fonte. ","")&IF(K207="","🟡 Classifique a categoria de limite. ","")&IF(TRIM(M207)="","🔴 Sem justificativa de vínculo: se não explica, não coloque. ","")&IF(N207<>"Sim","🟡 Preço de mercado não conferido. ","")&IF(O207="Sim","🔴 Possível DUPLA COBERTURA: a mesma despesa não pode ser paga duas vezes. ","")&IF(AND(L207="Sim",K207<>"Remuneração do proponente"),"🟡 Pessoa vinculada: este valor SOMA no limite de remuneração do proponente. ","")&IF(P207="","",IF(P207>L_FORNECEDOR,"🔴 Fornecedor acima do limite sobre o valor captado (confira exceções). ",IF(P207>=L_FORNECEDOR*MARGEM,"🟡 Fornecedor perto do limite. ","")))&IF(AND(LEFT(K207,5)="Cachê",F207<>""),IF(F207>IFERROR(VLOOKUP(K207,TAB_CATEGORIAS,2,FALSE),9E+99),"🔴 Cachê acima do limite: só com outras fontes ou apreciação da CNIC. ",""),"")&IF(AND(LEFT(H207,6)="Outras",K207<>""),"🟡 Outras fontes: confirme que o recurso existe e está comprometido. ",""))))

Sheet CRONOGRAMA
A1: PLANILHA 3 — CRONOGRAMA
A2: Não prometa no cronograma aquilo que o orçamento não consegue executar. Toda etapa com atividade precisa ter despesa no ORÇAMENTO (ou justificar por que não tem custo).
A3: Início do projeto
A4: Fim do projeto
A5: Duração total (meses) | B5: =IF(OR(B3="",B4=""),"",DATEDIF(B3,B4,"m")+1) | C5: =IF(B5="","",IF(B5>36,"🔴 Acima de 36 meses de execução (confira a IN)","🟢 Dentro de 36 meses"))
A7: Atividade | B7: Etapa | C7: Início | D7: Fim | E7: Duração (dias) | F7: Responsável | G7: Observações | H7: ALERTAS | I7: =IF($B$3="","",DATE(YEAR($B$3),MONTH($B$3),1)) | J7: =IF(I7="","",EDATE(I7,1)) | K7: =IF(J7="","",EDATE(J7,1)) | L7: =IF(K7="","",EDATE(K7,1)) | M7: =IF(L7="","",EDATE(L7,1)) | N7: =IF(M7="","",EDATE(M7,1)) | O7: =IF(N7="","",EDATE(N7,1)) | P7: =IF(O7="","",EDATE(O7,1)) | Q7: =IF(P7="","",EDATE(P7,1)) | ... Z7: =IF(Y7="","",EDATE(Y7,1))
E8: =IF(OR(C8="",D8=""),"",D8-C8+1) | H8: =IF(A8="","",IF(IF(A8="","",IF(OR(C8="",D8=""),"🟡 Falta data. ",IF(D8<C8,"🔴 Fim antes do início. ","")&IF(OR(AND($B$3<>"",C8<$B$3),AND($B$4<>"",D8>$B$4)),"🔴 Fora do período do projeto. ",""))&IF(B8="","🟡 Informe a etapa. ",IF(COUNTIF('ORÇAMENTO'!$A$8:$A$207,B8)=0,"🟡 Etapa sem despesa no orçamento: quem paga? ",""))&IF(F8="","🟡 Sem responsável. ",""))="","🟢 OK",IF(A8="","",IF(OR(C8="",D8=""),"🟡 Falta data. ",IF(D8<C8,"🔴 Fim antes do início. ","")&IF(OR(AND($B$3<>"",C8<$B$3),AND($B$4<>"",D8>$B$4)),"🔴 Fora do período do projeto. ",""))&IF(B8="","🟡 Informe a etapa. ",IF(COUNTIF('ORÇAMENTO'!$A$8:$A$207,B8)=0,"🟡 Etapa sem despesa no orçamento: quem paga? ",""))&IF(F8="","🟡 Sem responsável. ","")))) | I8: =IF(OR($C8="",$D8="",I$7=""),"",IF(AND($C8<=EOMONTH(I$7,0),$D8>=I$7),"■","")) | J8: =IF(OR($C8="",$D8="",J$7=""),"",IF(AND($C8<=EOMONTH(J$7,0),$D8>=J$7),"■","")) | K8: =IF(OR($C8="",$D8="",K$7=""),"",IF(AND($C8<=EOMONTH(K$7,0),$D8>=K$7),"■","")) | L8: =IF(OR($C8="",$D8="",L$7=""),"",IF(AND($C8<=EOMONTH(L$7,0),$D8>=L$7),"■","")) | M8: =IF(OR($C8="",$D8="",M$7=""),"",IF(AND($C8<=EOMONTH(M$7,0),$D8>=M$7),"■","")) | N8: =IF(OR($C8="",$D8="",N$7=""),"",IF(AND($C8<=EOMONTH(N$7,0),$D8>=N$7),"■","")) | O8: =IF(OR($C8="",$D8="",O$7=""),"",IF(AND($C8<=EOMONTH(O$7,0),$D8>=O$7),"■","")) | P8: =IF(OR($C8="",$D8="",P$7=""),"",IF(AND($C8<=EOMONTH(P$7,0),$D8>=P$7),"■","")) | ... Z8: =IF(OR($C8="",$D8="",Z$7=""),"",IF(AND($C8<=EOMONTH(Z$7,0),$D8>=Z$7),"■",""))
E9: =IF(OR(C9="",D9=""),"",D9-C9+1) | H9: =IF(A9="","",IF(IF(A9="","",IF(OR(C9="",D9=""),"🟡 Falta data. ",IF(D9<C9,"🔴 Fim antes do início. ","")&IF(OR(AND($B$3<>"",C9<$B$3),AND($B$4<>"",D9>$B$4)),"🔴 Fora do período do projeto. ",""))&IF(B9="","🟡 Informe a etapa. ",IF(COUNTIF('ORÇAMENTO'!$A$8:$A$207,B9)=0,"🟡 Etapa sem despesa no orçamento: quem paga? ",""))&IF(F9="","🟡 Sem responsável. ",""))="","🟢 OK",IF(A9="","",IF(OR(C9="",D9=""),"🟡 Falta data. ",IF(D9<C9,"🔴 Fim antes do início. ","")&IF(OR(AND($B$3<>"",C9<$B$3),AND($B$4<>"",D9>$B$4)),"🔴 Fora do período do projeto. ",""))&IF(B9="","🟡 Informe a etapa. ",IF(COUNTIF('ORÇAMENTO'!$A$8:$A$207,B9)=0,"🟡 Etapa sem despesa no orçamento: quem paga? ",""))&IF(F9="","🟡 Sem responsável. ","")))) | I9: =IF(OR($C9="",$D9="",I$7=""),"",IF(AND($C9<=EOMONTH(I$7,0),$D9>=I$7),"■","")) | J9: =IF(OR($C9="",$D9="",J$7=""),"",IF(AND($C9<=EOMONTH(J$7,0),$D9>=J$7),"■","")) | K9: =IF(OR($C9="",$D9="",K$7=""),"",IF(AND($C9<=EOMONTH(K$7,0),$D9>=K$7),"■","")) | L9: =IF(OR($C9="",$D9="",L$7=""),"",IF(AND($C9<=EOMONTH(L$7,0),$D9>=L$7),"■","")) | M9: =IF(OR($C9="",$D9="",M$7=""),"",IF(AND($C9<=EOMONTH(M$7,0),$D9>=M$7),"■","")) | N9: =IF(OR($C9="",$D9="",N$7=""),"",IF(AND($C9<=EOMONTH(N$7,0),$D9>=N$7),"■","")) | O9: =IF(OR($C9="",$D9="",O$7=""),"",IF(AND($C9<=EOMONTH(O$7,0),$D9>=O$7),"■","")) | P9: =IF(OR($C9="",$D9="",P$7=""),"",IF(AND($C9<=EOMONTH(P$7,0),$D9>=P$7),"■","")) | ... Z9: =IF(OR($C9="",$D9="",Z$7=""),"",IF(AND($C9<=EOMONTH(Z$7,0),$D9>=Z$7),"■",""))
E10: =IF(OR(C10="",D10=""),"",D10-C10+1) | H10: =IF(A10="","",IF(IF(A10="","",IF(OR(C10="",D10=""),"🟡 Falta data. ",IF(D10<C10,"🔴 Fim antes do início. ","")&IF(OR(AND($B$3<>"",C10<$B$3),AND($B$4<>"",D10>$B$4)),"🔴 Fora do período do projeto. ",""))&IF(B10="","🟡 Informe a etapa. ",IF(COUNTIF('ORÇAMENTO'!$A$8:$A$207,B10)=0,"🟡 Etapa sem despesa no orçamento: quem paga? ",""))&IF(F10="","🟡 Sem responsável. ",""))="","🟢 OK",IF(A10="","",IF(OR(C10="",D10=""),"🟡 Falta data. ",IF(D10<C10,"🔴 Fim antes do início. ","")&IF(OR(AND($B$3<>"",C10<$B$3),AND($B$4<>"",D10>$B$4)),"🔴 Fora do período do projeto. ",""))&IF(B10="","🟡 Informe a etapa. ",IF(COUNTIF('ORÇAMENTO'!$A$8:$A$207,B10)=0,"🟡 Etapa sem despesa no orçamento: quem paga? ",""))&IF(F10="","🟡 Sem responsável. ","")))) | I10: =IF(OR($C10="",$D10="",I$7=""),"",IF(AND($C10<=EOMONTH(I$7,0),$D10>=I$7),"■","")) | J10: =IF(OR($C10="",$D10="",J$7=""),"",IF(AND($C10<=EOMONTH(J$7,0),$D10>=J$7),"■","")) | K10: =IF(OR($C10="",$D10="",K$7=""),"",IF(AND($C10<=EOMONTH(K$7,0),$D10>=K$7),"■","")) | L10: =IF(OR($C10="",$D10="",L$7=""),"",IF(AND($C10<=EOMONTH(L$7,0),$D10>=L$7),"■","")) | M10: =IF(OR($C10="",$D10="",M$7=""),"",IF(AND($C10<=EOMONTH(M$7,0),$D10>=M$7),"■","")) | N10: =IF(OR($C10="",$D10="",N$7=""),"",IF(AND($C10<=EOMONTH(N$7,0),$D10>=N$7),"■","")) | O10: =IF(OR($C10="",$D10="",O$7=""),"",IF(AND($C10<=EOMONTH(O$7,0),$D10>=O$7),"■","")) | P10: =IF(OR($C10="",$D10="",P$7=""),"",IF(AND($C10<=EOMONTH(P$7,0),$D10>=P$7),"■","")) | ... Z10: =IF(OR($C10="",$D10="",Z$7=""),"",IF(AND($C10<=EOMONTH(Z$7,0),$D10>=Z$7),"■",""))
E11: =IF(OR(C11="",D11=""),"",D11-C11+1) | H11: =IF(A11="","",IF(IF(A11="","",IF(OR(C11="",D11=""),"🟡 Falta data. ",IF(D11<C11,"🔴 Fim antes do início. ","")&IF(OR(AND($B$3<>"",C11<$B$3),AND($B$4<>"",D11>$B$4)),"🔴 Fora do período do projeto. ",""))&IF(B11="","🟡 Informe a etapa. ",IF(COUNTIF('ORÇAMENTO'!$A$8:$A$207,B11)=0,"🟡 Etapa sem despesa no orçamento: quem paga? ",""))&IF(F11="","🟡 Sem responsável. ",""))="","🟢 OK",IF(A11="","",IF(OR(C11="",D11=""),"🟡 Falta data. ",IF(D11<C11,"🔴 Fim antes do início. ","")&IF(OR(AND($B$3<>"",C11<$B$3),AND($B$4<>"",D11>$B$4)),"🔴 Fora do período do projeto. ",""))&IF(B11="","🟡 Informe a etapa. ",IF(COUNTIF('ORÇAMENTO'!$A$8:$A$207,B11)=0,"🟡 Etapa sem despesa no orçamento: quem paga? ",""))&IF(F11="","🟡 Sem responsável. ","")))) | I11: =IF(OR($C11="",$D11="",I$7=""),"",IF(AND($C11<=EOMONTH(I$7,0),$D11>=I$7),"■","")) | J11: =IF(OR($C11="",$D11="",J$7=""),"",IF(AND($C11<=EOMONTH(J$7,0),$D11>=J$7),"■","")) | K11: =IF(OR($C11="",$D11="",K$7=""),"",IF(AND($C11<=EOMONTH(K$7,0),$D11>=K$7),"■","")) | L11: =IF(OR($C11="",$D11="",L$7=""),"",IF(AND($C11<=EOMONTH(L$7,0),$D11>=L$7),"■","")) | M11: =IF(OR($C11="",$D11="",M$7=""),"",IF(AND($C11<=EOMONTH(M$7,0),$D11>=M$7),"■","")) | N11: =IF(OR($C11="",$D11="",N$7=""),"",IF(AND($C11<=EOMONTH(N$7,0),$D11>=N$7),"■","")) | O11: =IF(OR($C11="",$D11="",O$7=""),"",IF(AND($C11<=EOMONTH(O$7,0),$D11>=O$7),"■","")) | P11: =IF(OR($C11="",$D11="",P$7=""),"",IF(AND($C11<=EOMONTH(P$7,0),$D11>=P$7),"■","")) | ... Z11: =IF(OR($C11="",$D11="",Z$7=""),"",IF(AND($C11<=EOMONTH(Z$7,0),$D11>=Z$7),"■",""))
E12: =IF(OR(C12="",D12=""),"",D12-C12+1) | H12: =IF(A12="","",IF(IF(A12="","",IF(OR(C12="",D12=""),"🟡 Falta data. ",IF(D12<C12,"🔴 Fim antes do início. ","")&IF(OR(AND($B$3<>"",C12<$B$3),AND($B$4<>"",D12>$B$4)),"🔴 Fora do período do projeto. ",""))&IF(B12="","🟡 Informe a etapa. ",IF(COUNTIF('ORÇAMENTO'!$A$8:$A$207,B12)=0,"🟡 Etapa sem despesa no orçamento: quem paga? ",""))&IF(F12="","🟡 Sem responsável. ",""))="","🟢 OK",IF(A12="","",IF(OR(C12="",D12=""),"🟡 Falta data. ",IF(D12<C12,"🔴 Fim antes do início. ","")&IF(OR(AND($B$3<>"",C12<$B$3),AND($B$4<>"",D12>$B$4)),"🔴 Fora do período do projeto. ",""))&IF(B12="","🟡 Informe a etapa. ",IF(COUNTIF('ORÇAMENTO'!$A$8:$A$207,B12)=0,"🟡 Etapa sem despesa no orçamento: quem paga? ",""))&IF(F12="","🟡 Sem responsável. ","")))) | I12: =IF(OR($C12="",$D12="",I$7=""),"",IF(AND($C12<=EOMONTH(I$7,0),$D12>=I$7),"■","")) | J12: =IF(OR($C12="",$D12="",J$7=""),"",IF(AND($C12<=EOMONTH(J$7,0),$D12>=J$7),"■","")) | K12: =IF(OR($C12="",$D12="",K$7=""),"",IF(AND($C12<=EOMONTH(K$7,0),$D12>=K$7),"■","")) | L12: =IF(OR($C12="",$D12="",L$7=""),"",IF(AND($C12<=EOMONTH(L$7,0),$D12>=L$7),"■","")) | M12: =IF(OR($C12="",$D12="",M$7=""),"",IF(AND($C12<=EOMONTH(M$7,0),$D12>=M$7),"■","")) | N12: =IF(OR($C12="",$D12="",N$7=""),"",IF(AND($C12<=EOMONTH(N$7,0),$D12>=N$7),"■","")) | O12: =IF(OR($C12="",$D12="",O$7=""),"",IF(AND($C12<=EOMONTH(O$7,0),$D12>=O$7),"■","")) | P12: =IF(OR($C12="",$D12="",P$7=""),"",IF(AND($C12<=EOMONTH(P$7,0),$D12>=P$7),"■","")) | ... Z12: =IF(OR($C12="",$D12="",Z$7=""),"",IF(AND($C12<=EOMONTH(Z$7,0),$D12>=Z$7),"■",""))
E13: =IF(OR(C13="",D13=""),"",D13-C13+1) | H13: =IF(A13="","",IF(IF(A13="","",IF(OR(C13="",D13=""),"🟡 Falta data. ",IF(D13<C13,"🔴 Fim antes do início. ","")&IF(OR(AND($B$3<>"",C13<$B$3),AND($B$4<>"",D13>$B$4)),"🔴 Fora do período do projeto. ",""))&IF(B13="","🟡 Informe a etapa. ",IF(COUNTIF('ORÇAMENTO'!$A$8:$A$207,B13)=0,"🟡 Etapa sem despesa no orçamento: quem paga? ",""))&IF(F13="","🟡 Sem responsável. ",""))="","🟢 OK",IF(A13="","",IF(OR(C13="",D13=""),"🟡 Falta data. ",IF(D13<C13,"🔴 Fim antes do início. ","")&IF(OR(AND($B$3<>"",C13<$B$3),AND($B$4<>"",D13>$B$4)),"🔴 Fora do período do projeto. ",""))&IF(B13="","🟡 Informe a etapa. ",IF(COUNTIF('ORÇAMENTO'!$A$8:$A$207,B13)=0,"🟡 Etapa sem despesa no orçamento: quem paga? ",""))&IF(F13="","🟡 Sem responsável. ","")))) | I13: =IF(OR($C13="",$D13="",I$7=""),"",IF(AND($C13<=EOMONTH(I$7,0),$D13>=I$7),"■","")) | J13: =IF(OR($C13="",$D13="",J$7=""),"",IF(AND($C13<=EOMONTH(J$7,0),$D13>=J$7),"■","")) | K13: =IF(OR($C13="",$D13="",K$7=""),"",IF(AND($C13<=EOMONTH(K$7,0),$D13>=K$7),"■","")) | L13: =IF(OR($C13="",$D13="",L$7=""),"",IF(AND($C13<=EOMONTH(L$7,0),$D13>=L$7),"■","")) | M13: =IF(OR($C13="",$D13="",M$7=""),"",IF(AND($C13<=EOMONTH(M$7,0),$D13>=M$7),"■","")) | N13: =IF(OR($C13="",$D13="",N$7=""),"",IF(AND($C13<=EOMONTH(N$7,0),$D13>=N$7),"■","")) | O13: =IF(OR($C13="",$D13="",O$7=""),"",IF(AND($C13<=EOMONTH(O$7,0),$D13>=O$7),"■","")) | P13: =IF(OR($C13="",$D13="",P$7=""),"",IF(AND($C13<=EOMONTH(P$7,0),$D13>=P$7),"■","")) | ... Z13: =IF(OR($C13="",$D13="",Z$7=""),"",IF(AND($C13<=EOMONTH(Z$7,0),$D13>=Z$7),"■",""))
E14: =IF(OR(C14="",D14=""),"",D14-C14+1) | H14: =IF(A14="","",IF(IF(A14="","",IF(OR(C14="",D14=""),"🟡 Falta data. ",IF(D14<C14,"🔴 Fim antes do início. ","")&IF(OR(AND($B$3<>"",C14<$B$3),AND($B$4<>"",D14>$B$4)),"🔴 Fora do período do projeto. ",""))&IF(B14="","🟡 Informe a etapa. ",IF(COUNTIF('ORÇAMENTO'!$A$8:$A$207,B14)=0,"🟡 Etapa sem despesa no orçamento: quem paga? ",""))&IF(F14="","🟡 Sem responsável. ",""))="","🟢 OK",IF(A14="","",IF(OR(C14="",D14=""),"🟡 Falta data. ",IF(D14<C14,"🔴 Fim antes do início. ","")&IF(OR(AND($B$3<>"",C14<$B$3),AND($B$4<>"",D14>$B$4)),"🔴 Fora do período do projeto. ",""))&IF(B14="","🟡 Informe a etapa. ",IF(COUNTIF('ORÇAMENTO'!$A$8:$A$207,B14)=0,"🟡 Etapa sem despesa no orçamento: quem paga? ",""))&IF(F14="","🟡 Sem responsável. ","")))) | I14: =IF(OR($C14="",$D14="",I$7=""),"",IF(AND($C14<=EOMONTH(I$7,0),$D14>=I$7),"■","")) | J14: =IF(OR($C14="",$D14="",J$7=""),"",IF(AND($C14<=EOMONTH(J$7,0),$D14>=J$7),"■","")) | K14: =IF(OR($C14="",$D14="",K$7=""),"",IF(AND($C14<=EOMONTH(K$7,0),$D14>=K$7),"■","")) | L14: =IF(OR($C14="",$D14="",L$7=""),"",IF(AND($C14<=EOMONTH(L$7,0),$D14>=L$7),"■","")) | M14: =IF(OR($C14="",$D14="",M$7=""),"",IF(AND($C14<=EOMONTH(M$7,0),$D14>=M$7),"■","")) | N14: =IF(OR($C14="",$D14="",N$7=""),"",IF(AND($C14<=EOMONTH(N$7,0),$D14>=N$7),"■","")) | O14: =IF(OR($C14="",$D14="",O$7=""),"",IF(AND($C14<=EOMONTH(O$7,0),$D14>=O$7),"■","")) | P14: =IF(OR($C14="",$D14="",P$7=""),"",IF(AND($C14<=EOMONTH(P$7,0),$D14>=P$7),"■","")) | ... Z14: =IF(OR($C14="",$D14="",Z$7=""),"",IF(AND($C14<=EOMONTH(Z$7,0),$D14>=Z$7),"■",""))
E15: =IF(OR(C15="",D15=""),"",D15-C15+1) | H15: =IF(A15="","",IF(IF(A15="","",IF(OR(C15="",D15=""),"🟡 Falta data. ",IF(D15<C15,"🔴 Fim antes do início. ","")&IF(OR(AND($B$3<>"",C15<$B$3),AND($B$4<>"",D15>$B$4)),"🔴 Fora do período do projeto. ",""))&IF(B15="","🟡 Informe a etapa. ",IF(COUNTIF('ORÇAMENTO'!$A$8:$A$207,B15)=0,"🟡 Etapa sem despesa no orçamento: quem paga? ",""))&IF(F15="","🟡 Sem responsável. ",""))="","🟢 OK",IF(A15="","",IF(OR(C15="",D15=""),"🟡 Falta data. ",IF(D15<C15,"🔴 Fim antes do início. ","")&IF(OR(AND($B$3<>"",C15<$B$3),AND($B$4<>"",D15>$B$4)),"🔴 Fora do período do projeto. ",""))&IF(B15="","🟡 Informe a etapa. ",IF(COUNTIF('ORÇAMENTO'!$A$8:$A$207,B15)=0,"🟡 Etapa sem despesa no orçamento: quem paga? ",""))&IF(F15="","🟡 Sem responsável. ","")))) | I15: =IF(OR($C15="",$D15="",I$7=""),"",IF(AND($C15<=EOMONTH(I$7,0),$D15>=I$7),"■","")) | J15: =IF(OR($C15="",$D15="",J$7=""),"",IF(AND($C15<=EOMONTH(J$7,0),$D15>=J$7),"■","")) | K15: =IF(OR($C15="",$D15="",K$7=""),"",IF(AND($C15<=EOMONTH(K$7,0),$D15>=K$7),"■","")) | L15: =IF(OR($C15="",$D15="",L$7=""),"",IF(AND($C15<=EOMONTH(L$7,0),$D15>=L$7),"■","")) | M15: =IF(OR($C15="",$D15="",M$7=""),"",IF(AND($C15<=EOMONTH(M$7,0),$D15>=M$7),"■","")) | N15: =IF(OR($C15="",$D15="",N$7=""),"",IF(AND($C15<=EOMONTH(N$7,0),$D15>=N$7),"■","")) | O15: =IF(OR($C15="",$D15="",O$7=""),"",IF(AND($C15<=EOMONTH(O$7,0),$D15>=O$7),"■","")) | P15: =IF(OR($C15="",$D15="",P$7=""),"",IF(AND($C15<=EOMONTH(P$7,0),$D15>=P$7),"■","")) | ... Z15: =IF(OR($C15="",$D15="",Z$7=""),"",IF(AND($C15<=EOMONTH(Z$7,0),$D15>=Z$7),"■",""))
